[2025-05-18 13:07:07][INFO] Processing request: GET test
[2025-05-18 13:07:07][INFO] Response sent (HTTP 200): {"status":"ok","message":"Odoo proxy is running","timestamp":"2025-05-18T13:07:07+00:00","version":"1.0.0","php_version":"7.4.33","methods":["authenticate","materials","test_connection"]}...
[2025-05-18 13:07:07][INFO] Processing request: GET authenticate
[2025-05-18 13:07:07][INFO] Starting authentication with Odoo
[2025-05-18 13:07:09][ERROR] Odoo authentication error: {"code":0,"message":"Odoo Server Error","data":{"name":"odoo.exceptions.AccessDenied","debug":"Traceback (most recent call last):\n  File \"\/home\/odoo\/src\/odoo\/saas-18.2\/odoo\/http.py\", line 2016, in _transactioning\n    return service_model.retrying(func, env=self.env)\n           ^^^^^^^^^^^^^^^^^^^^^^^^^^^^^^^^^^^^^^^^^^\n  File \"\/home\/odoo\/src\/odoo\/saas-18.2\/odoo\/service\/model.py\", line 161, in retrying\n    result = func()\n             ^^^^^^\n  File \"\/home\/odoo\/src\/odoo\/saas-18.2\/odoo\/http.py\", line 1983, in _serve_ir_http\n    response = self.dispatcher.dispatch(rule.endpoint, args)\n               ^^^^^^^^^^^^^^^^^^^^^^^^^^^^^^^^^^^^^^^^^^^^^\n  File \"\/home\/odoo\/src\/odoo\/saas-18.2\/odoo\/http.py\", line 2234, in dispatch\n    result = self.request.registry['ir.http']._dispatch(endpoint)\n             ^^^^^^^^^^^^^^^^^^^^^^^^^^^^^^^^^^^^^^^^^^^^^^^^^^^^\n  File \"\/home\/odoo\/src\/odoo\/saas-18.2\/odoo\/addons\/base\/models\/ir_http.py\", line 340, in _dispatch\n    result = endpoint(**request.params)\n             ^^^^^^^^^^^^^^^^^^^^^^^^^^\n  File \"\/home\/odoo\/src\/odoo\/saas-18.2\/odoo\/http.py\", line 745, in route_wrapper\n    result = endpoint(self, *args, **params_ok)\n             ^^^^^^^^^^^^^^^^^^^^^^^^^^^^^^^^^^\n  File \"\/home\/odoo\/src\/odoo\/saas-18.2\/addons\/web\/controllers\/session.py\", line 46, in authenticate\n    auth_info = request.session.authenticate(env, credential)\n                ^^^^^^^^^^^^^^^^^^^^^^^^^^^^^^^^^^^^^^^^^^^^^\n  File \"\/home\/odoo\/src\/odoo\/saas-18.2\/odoo\/http.py\", line 1100, in authenticate\n    auth_info = env['res.users'].authenticate(credential, wsgienv)\n                ^^^^^^^^^^^^^^^^^^^^^^^^^^^^^^^^^^^^^^^^^^^^^^^^^^\n  File \"\/home\/odoo\/src\/odoo\/saas-18.2\/addons\/auth_totp_mail\/models\/res_users.py\", line 51, in authenticate\n    auth_info = super().authenticate(credential, user_agent_env)\n                ^^^^^^^^^^^^^^^^^^^^^^^^^^^^^^^^^^^^^^^^^^^^^^^^\n  File \"\/home\/odoo\/src\/odoo\/saas-18.2\/odoo\/addons\/base\/models\/res_users.py\", line 757, in authenticate\n    auth_info = self._login(credential, user_agent_env=user_agent_env)\n                ^^^^^^^^^^^^^^^^^^^^^^^^^^^^^^^^^^^^^^^^^^^^^^^^^^^^^^\n  File \"\/home\/odoo\/src\/custom\/trial\/saas_trial\/models\/res_users.py\", line 382, in _login\n    auth_info = super()._login(credential, user_agent_env=user_agent_env)\n                ^^^^^^^^^^^^^^^^^^^^^^^^^^^^^^^^^^^^^^^^^^^^^^^^^^^^^^^^^\n  File \"\/home\/odoo\/src\/odoo\/saas-18.2\/odoo\/addons\/base\/models\/res_users.py\", line 728, in _login\n    auth_info = user._check_credentials(credential, user_agent_env)\n                ^^^^^^^^^^^^^^^^^^^^^^^^^^^^^^^^^^^^^^^^^^^^^^^^^^^\n  File \"\/home\/odoo\/src\/custom\/trial\/saas_trial\/models\/res_users.py\", line 315, in _check_credentials\n    raise access_denied\n  File \"\/home\/odoo\/src\/custom\/trial\/saas_trial\/models\/res_users.py\", line 227, in _check_credentials\n    return super(ResUsers, self)._check_credentials(credential, env)\n           ^^^^^^^^^^^^^^^^^^^^^^^^^^^^^^^^^^^^^^^^^^^^^^^^^^^^^^^^^\n  File \"\/home\/odoo\/src\/odoo\/saas-18.2\/odoo\/addons\/base\/models\/res_users.py\", line 369, in _check_credentials\n    raise AccessDenied()\nodoo.exceptions.AccessDenied: Access Denied\n","message":"Access Denied","arguments":["Access Denied"],"context":[]}}
[2025-05-18 13:07:09][INFO] Response sent (HTTP 500): {"jsonrpc":"2.0","id":325257,"error":{"code":0,"message":"Odoo Server Error","data":{"name":"odoo.exceptions.AccessDenied","debug":"Traceback (most recent call last):\n  File \"\/home\/odoo\/src\/odoo...
[2025-05-18 13:08:23][INFO] Processing request: GET test
[2025-05-18 13:08:23][INFO] Response sent (HTTP 200): {"status":"ok","message":"Odoo proxy is running","timestamp":"2025-05-18T13:08:23+00:00","version":"1.0.0","php_version":"7.4.33","methods":["authenticate","materials","test_connection"]}...
[2025-05-18 13:08:23][INFO] Processing request: GET authenticate
[2025-05-18 13:08:23][INFO] Starting authentication with Odoo
[2025-05-18 13:08:25][ERROR] Odoo authentication error: {"code":0,"message":"Odoo Server Error","data":{"name":"odoo.exceptions.AccessDenied","debug":"Traceback (most recent call last):\n  File \"\/home\/odoo\/src\/odoo\/saas-18.2\/odoo\/http.py\", line 2016, in _transactioning\n    return service_model.retrying(func, env=self.env)\n           ^^^^^^^^^^^^^^^^^^^^^^^^^^^^^^^^^^^^^^^^^^\n  File \"\/home\/odoo\/src\/odoo\/saas-18.2\/odoo\/service\/model.py\", line 161, in retrying\n    result = func()\n             ^^^^^^\n  File \"\/home\/odoo\/src\/odoo\/saas-18.2\/odoo\/http.py\", line 1983, in _serve_ir_http\n    response = self.dispatcher.dispatch(rule.endpoint, args)\n               ^^^^^^^^^^^^^^^^^^^^^^^^^^^^^^^^^^^^^^^^^^^^^\n  File \"\/home\/odoo\/src\/odoo\/saas-18.2\/odoo\/http.py\", line 2234, in dispatch\n    result = self.request.registry['ir.http']._dispatch(endpoint)\n             ^^^^^^^^^^^^^^^^^^^^^^^^^^^^^^^^^^^^^^^^^^^^^^^^^^^^\n  File \"\/home\/odoo\/src\/odoo\/saas-18.2\/odoo\/addons\/base\/models\/ir_http.py\", line 340, in _dispatch\n    result = endpoint(**request.params)\n             ^^^^^^^^^^^^^^^^^^^^^^^^^^\n  File \"\/home\/odoo\/src\/odoo\/saas-18.2\/odoo\/http.py\", line 745, in route_wrapper\n    result = endpoint(self, *args, **params_ok)\n             ^^^^^^^^^^^^^^^^^^^^^^^^^^^^^^^^^^\n  File \"\/home\/odoo\/src\/odoo\/saas-18.2\/addons\/web\/controllers\/session.py\", line 46, in authenticate\n    auth_info = request.session.authenticate(env, credential)\n                ^^^^^^^^^^^^^^^^^^^^^^^^^^^^^^^^^^^^^^^^^^^^^\n  File \"\/home\/odoo\/src\/odoo\/saas-18.2\/odoo\/http.py\", line 1100, in authenticate\n    auth_info = env['res.users'].authenticate(credential, wsgienv)\n                ^^^^^^^^^^^^^^^^^^^^^^^^^^^^^^^^^^^^^^^^^^^^^^^^^^\n  File \"\/home\/odoo\/src\/odoo\/saas-18.2\/addons\/auth_totp_mail\/models\/res_users.py\", line 51, in authenticate\n    auth_info = super().authenticate(credential, user_agent_env)\n                ^^^^^^^^^^^^^^^^^^^^^^^^^^^^^^^^^^^^^^^^^^^^^^^^\n  File \"\/home\/odoo\/src\/odoo\/saas-18.2\/odoo\/addons\/base\/models\/res_users.py\", line 757, in authenticate\n    auth_info = self._login(credential, user_agent_env=user_agent_env)\n                ^^^^^^^^^^^^^^^^^^^^^^^^^^^^^^^^^^^^^^^^^^^^^^^^^^^^^^\n  File \"\/home\/odoo\/src\/custom\/trial\/saas_trial\/models\/res_users.py\", line 382, in _login\n    auth_info = super()._login(credential, user_agent_env=user_agent_env)\n                ^^^^^^^^^^^^^^^^^^^^^^^^^^^^^^^^^^^^^^^^^^^^^^^^^^^^^^^^^\n  File \"\/home\/odoo\/src\/odoo\/saas-18.2\/odoo\/addons\/base\/models\/res_users.py\", line 728, in _login\n    auth_info = user._check_credentials(credential, user_agent_env)\n                ^^^^^^^^^^^^^^^^^^^^^^^^^^^^^^^^^^^^^^^^^^^^^^^^^^^\n  File \"\/home\/odoo\/src\/custom\/trial\/saas_trial\/models\/res_users.py\", line 315, in _check_credentials\n    raise access_denied\n  File \"\/home\/odoo\/src\/custom\/trial\/saas_trial\/models\/res_users.py\", line 227, in _check_credentials\n    return super(ResUsers, self)._check_credentials(credential, env)\n           ^^^^^^^^^^^^^^^^^^^^^^^^^^^^^^^^^^^^^^^^^^^^^^^^^^^^^^^^^\n  File \"\/home\/odoo\/src\/odoo\/saas-18.2\/odoo\/addons\/base\/models\/res_users.py\", line 369, in _check_credentials\n    raise AccessDenied()\nodoo.exceptions.AccessDenied: Access Denied\n","message":"Access Denied","arguments":["Access Denied"],"context":[]}}
[2025-05-18 13:08:25][INFO] Response sent (HTTP 500): {"jsonrpc":"2.0","id":461830,"error":{"code":0,"message":"Odoo Server Error","data":{"name":"odoo.exceptions.AccessDenied","debug":"Traceback (most recent call last):\n  File \"\/home\/odoo\/src\/odoo...
[2025-05-18 13:09:31][INFO] Processing request: GET authenticate
[2025-05-18 13:09:31][INFO] Starting authentication with Odoo
[2025-05-18 13:09:33][ERROR] Odoo authentication error: {"code":0,"message":"Odoo Server Error","data":{"name":"odoo.exceptions.AccessDenied","debug":"Traceback (most recent call last):\n  File \"\/home\/odoo\/src\/odoo\/saas-18.2\/odoo\/http.py\", line 2016, in _transactioning\n    return service_model.retrying(func, env=self.env)\n           ^^^^^^^^^^^^^^^^^^^^^^^^^^^^^^^^^^^^^^^^^^\n  File \"\/home\/odoo\/src\/odoo\/saas-18.2\/odoo\/service\/model.py\", line 161, in retrying\n    result = func()\n             ^^^^^^\n  File \"\/home\/odoo\/src\/odoo\/saas-18.2\/odoo\/http.py\", line 1983, in _serve_ir_http\n    response = self.dispatcher.dispatch(rule.endpoint, args)\n               ^^^^^^^^^^^^^^^^^^^^^^^^^^^^^^^^^^^^^^^^^^^^^\n  File \"\/home\/odoo\/src\/odoo\/saas-18.2\/odoo\/http.py\", line 2234, in dispatch\n    result = self.request.registry['ir.http']._dispatch(endpoint)\n             ^^^^^^^^^^^^^^^^^^^^^^^^^^^^^^^^^^^^^^^^^^^^^^^^^^^^\n  File \"\/home\/odoo\/src\/odoo\/saas-18.2\/odoo\/addons\/base\/models\/ir_http.py\", line 340, in _dispatch\n    result = endpoint(**request.params)\n             ^^^^^^^^^^^^^^^^^^^^^^^^^^\n  File \"\/home\/odoo\/src\/odoo\/saas-18.2\/odoo\/http.py\", line 745, in route_wrapper\n    result = endpoint(self, *args, **params_ok)\n             ^^^^^^^^^^^^^^^^^^^^^^^^^^^^^^^^^^\n  File \"\/home\/odoo\/src\/odoo\/saas-18.2\/addons\/web\/controllers\/session.py\", line 46, in authenticate\n    auth_info = request.session.authenticate(env, credential)\n                ^^^^^^^^^^^^^^^^^^^^^^^^^^^^^^^^^^^^^^^^^^^^^\n  File \"\/home\/odoo\/src\/odoo\/saas-18.2\/odoo\/http.py\", line 1100, in authenticate\n    auth_info = env['res.users'].authenticate(credential, wsgienv)\n                ^^^^^^^^^^^^^^^^^^^^^^^^^^^^^^^^^^^^^^^^^^^^^^^^^^\n  File \"\/home\/odoo\/src\/odoo\/saas-18.2\/addons\/auth_totp_mail\/models\/res_users.py\", line 51, in authenticate\n    auth_info = super().authenticate(credential, user_agent_env)\n                ^^^^^^^^^^^^^^^^^^^^^^^^^^^^^^^^^^^^^^^^^^^^^^^^\n  File \"\/home\/odoo\/src\/odoo\/saas-18.2\/odoo\/addons\/base\/models\/res_users.py\", line 757, in authenticate\n    auth_info = self._login(credential, user_agent_env=user_agent_env)\n                ^^^^^^^^^^^^^^^^^^^^^^^^^^^^^^^^^^^^^^^^^^^^^^^^^^^^^^\n  File \"\/home\/odoo\/src\/custom\/trial\/saas_trial\/models\/res_users.py\", line 382, in _login\n    auth_info = super()._login(credential, user_agent_env=user_agent_env)\n                ^^^^^^^^^^^^^^^^^^^^^^^^^^^^^^^^^^^^^^^^^^^^^^^^^^^^^^^^^\n  File \"\/home\/odoo\/src\/odoo\/saas-18.2\/odoo\/addons\/base\/models\/res_users.py\", line 728, in _login\n    auth_info = user._check_credentials(credential, user_agent_env)\n                ^^^^^^^^^^^^^^^^^^^^^^^^^^^^^^^^^^^^^^^^^^^^^^^^^^^\n  File \"\/home\/odoo\/src\/custom\/trial\/saas_trial\/models\/res_users.py\", line 315, in _check_credentials\n    raise access_denied\n  File \"\/home\/odoo\/src\/custom\/trial\/saas_trial\/models\/res_users.py\", line 227, in _check_credentials\n    return super(ResUsers, self)._check_credentials(credential, env)\n           ^^^^^^^^^^^^^^^^^^^^^^^^^^^^^^^^^^^^^^^^^^^^^^^^^^^^^^^^^\n  File \"\/home\/odoo\/src\/odoo\/saas-18.2\/odoo\/addons\/base\/models\/res_users.py\", line 369, in _check_credentials\n    raise AccessDenied()\nodoo.exceptions.AccessDenied: Access Denied\n","message":"Access Denied","arguments":["Access Denied"],"context":[]}}
[2025-05-18 13:09:33][INFO] Response sent (HTTP 500): {"jsonrpc":"2.0","id":834837,"error":{"code":0,"message":"Odoo Server Error","data":{"name":"odoo.exceptions.AccessDenied","debug":"Traceback (most recent call last):\n  File \"\/home\/odoo\/src\/odoo...
[2025-05-18 13:17:03][INFO] Processing request: GET test
[2025-05-18 13:17:03][INFO] Response sent (HTTP 200): {"status":"ok","message":"Odoo proxy is running","timestamp":"2025-05-18T13:17:03+00:00","version":"1.0.0","php_version":"7.4.33","methods":["authenticate","materials","test_connection"]}...
[2025-05-18 13:17:03][INFO] Processing request: GET authenticate
[2025-05-18 13:17:03][INFO] Starting authentication with Odoo
[2025-05-18 13:17:06][ERROR] Odoo authentication error: {"code":0,"message":"Odoo Server Error","data":{"name":"odoo.exceptions.AccessDenied","debug":"Traceback (most recent call last):\n  File \"\/home\/odoo\/src\/odoo\/saas-18.2\/odoo\/http.py\", line 2016, in _transactioning\n    return service_model.retrying(func, env=self.env)\n           ^^^^^^^^^^^^^^^^^^^^^^^^^^^^^^^^^^^^^^^^^^\n  File \"\/home\/odoo\/src\/odoo\/saas-18.2\/odoo\/service\/model.py\", line 161, in retrying\n    result = func()\n             ^^^^^^\n  File \"\/home\/odoo\/src\/odoo\/saas-18.2\/odoo\/http.py\", line 1983, in _serve_ir_http\n    response = self.dispatcher.dispatch(rule.endpoint, args)\n               ^^^^^^^^^^^^^^^^^^^^^^^^^^^^^^^^^^^^^^^^^^^^^\n  File \"\/home\/odoo\/src\/odoo\/saas-18.2\/odoo\/http.py\", line 2234, in dispatch\n    result = self.request.registry['ir.http']._dispatch(endpoint)\n             ^^^^^^^^^^^^^^^^^^^^^^^^^^^^^^^^^^^^^^^^^^^^^^^^^^^^\n  File \"\/home\/odoo\/src\/odoo\/saas-18.2\/odoo\/addons\/base\/models\/ir_http.py\", line 340, in _dispatch\n    result = endpoint(**request.params)\n             ^^^^^^^^^^^^^^^^^^^^^^^^^^\n  File \"\/home\/odoo\/src\/odoo\/saas-18.2\/odoo\/http.py\", line 745, in route_wrapper\n    result = endpoint(self, *args, **params_ok)\n             ^^^^^^^^^^^^^^^^^^^^^^^^^^^^^^^^^^\n  File \"\/home\/odoo\/src\/odoo\/saas-18.2\/addons\/web\/controllers\/session.py\", line 46, in authenticate\n    auth_info = request.session.authenticate(env, credential)\n                ^^^^^^^^^^^^^^^^^^^^^^^^^^^^^^^^^^^^^^^^^^^^^\n  File \"\/home\/odoo\/src\/odoo\/saas-18.2\/odoo\/http.py\", line 1100, in authenticate\n    auth_info = env['res.users'].authenticate(credential, wsgienv)\n                ^^^^^^^^^^^^^^^^^^^^^^^^^^^^^^^^^^^^^^^^^^^^^^^^^^\n  File \"\/home\/odoo\/src\/odoo\/saas-18.2\/addons\/auth_totp_mail\/models\/res_users.py\", line 51, in authenticate\n    auth_info = super().authenticate(credential, user_agent_env)\n                ^^^^^^^^^^^^^^^^^^^^^^^^^^^^^^^^^^^^^^^^^^^^^^^^\n  File \"\/home\/odoo\/src\/odoo\/saas-18.2\/odoo\/addons\/base\/models\/res_users.py\", line 757, in authenticate\n    auth_info = self._login(credential, user_agent_env=user_agent_env)\n                ^^^^^^^^^^^^^^^^^^^^^^^^^^^^^^^^^^^^^^^^^^^^^^^^^^^^^^\n  File \"\/home\/odoo\/src\/custom\/trial\/saas_trial\/models\/res_users.py\", line 382, in _login\n    auth_info = super()._login(credential, user_agent_env=user_agent_env)\n                ^^^^^^^^^^^^^^^^^^^^^^^^^^^^^^^^^^^^^^^^^^^^^^^^^^^^^^^^^\n  File \"\/home\/odoo\/src\/odoo\/saas-18.2\/odoo\/addons\/base\/models\/res_users.py\", line 728, in _login\n    auth_info = user._check_credentials(credential, user_agent_env)\n                ^^^^^^^^^^^^^^^^^^^^^^^^^^^^^^^^^^^^^^^^^^^^^^^^^^^\n  File \"\/home\/odoo\/src\/custom\/trial\/saas_trial\/models\/res_users.py\", line 315, in _check_credentials\n    raise access_denied\n  File \"\/home\/odoo\/src\/custom\/trial\/saas_trial\/models\/res_users.py\", line 227, in _check_credentials\n    return super(ResUsers, self)._check_credentials(credential, env)\n           ^^^^^^^^^^^^^^^^^^^^^^^^^^^^^^^^^^^^^^^^^^^^^^^^^^^^^^^^^\n  File \"\/home\/odoo\/src\/odoo\/saas-18.2\/odoo\/addons\/base\/models\/res_users.py\", line 369, in _check_credentials\n    raise AccessDenied()\nodoo.exceptions.AccessDenied: Access Denied\n","message":"Access Denied","arguments":["Access Denied"],"context":[]}}
[2025-05-18 13:17:06][INFO] Response sent (HTTP 500): {"jsonrpc":"2.0","id":333159,"error":{"code":0,"message":"Odoo Server Error","data":{"name":"odoo.exceptions.AccessDenied","debug":"Traceback (most recent call last):\n  File \"\/home\/odoo\/src\/odoo...
